<?xml version="1.0"?>
<sdf version='1.7'>
    <model name='shadow_hand'>
        <self_collide>false</self_collide>

        <!-- Fix To World -->
        <joint name="panda_joint_world" type="fixed">
            <parent>world</parent>
            <child>forearm</child>
        </joint>

        <!-- Forearm-Wrist-Palm Links -->
        <link name='forearm'>
            <self_collide>false</self_collide>
            <visual name='forearm_visual'>
                <geometry>
                    <mesh>
                        <uri>meshes/visual/forearm.dae</uri>
                    </mesh>
                </geometry>
            </visual>
            <collision name='forearm_collision'>
                <geometry>
                    <mesh>
                        <uri>meshes/collision/forearm.stl</uri>
                    </mesh>
                </geometry>
            </collision>
            <inertial>
                <pose>0.000158664 -0.000296214 0.0939161 0 0 0</pose>
                <mass>3.7341173015346683</mass>
                <inertia>
                    <ixx>0.014958642677085437</ixx>
                    <iyy>0.01495095678803383</iyy>
                    <izz>0.008312516810084897</izz>
                    <ixy>-1.4535374883756278e-07</ixy>
                    <ixz>8.503435743103697e-07</ixz>
                    <iyz>7.767903516635545e-05</iyz>
                </inertia>
            </inertial>
        </link>

        <link name='wrist'>
            <self_collide>false</self_collide>
            <pose relative_to='forearm_joint'>0 0 0 0 0 0</pose>
            <visual name='wrist_visual'>
                <geometry>
                    <mesh>
                        <uri>meshes/visual/wrist.dae</uri>
                    </mesh>
                </geometry>
            </visual>
            <collision name='wrist_collision'>
                <geometry>
                    <mesh>
                        <uri>meshes/collision/wrist.stl</uri>
                    </mesh>
                </geometry>
            </collision>
            <inertial>
                <pose>0.0019993 -4.78915e-05 0.0114012 0 0 0</pose>
                <mass>0.041829591028597575</mass>
                <inertia>
                    <ixx>1.1169284414636923e-05</ixx>
                    <iyy>2.5657211730082853e-05</iyy>
                    <izz>1.7706962551088734e-05</izz>
                    <ixy>-3.754588819476189e-09</ixy>
                    <ixz>-2.608147640679391e-07</ixz>
                    <iyz>-2.2829074606977278e-08</iyz>
                </inertia>
            </inertial>
        </link>

        <link name='palm'>
            <self_collide>false</self_collide>
            <pose relative_to='wrist_joint'>0 0 0 0 0 0</pose>
            <visual name='palm_visual'>
                <geometry>
                    <mesh>
                        <uri>meshes/visual/palm.dae</uri>
                    </mesh>
                </geometry>
            </visual>
            <collision name='palm_collision'>
                <geometry>
                    <mesh>
                        <uri>meshes/collision/palm.stl</uri>
                    </mesh>
                </geometry>
            </collision>
            <inertial>
                <pose>0.00560661 0.000168758 0.0406171 0 0 0</pose>
                <mass>0.17950902043639072</mass>
                <inertia>
                    <ixx>0.00015079195488992757</ixx>
                    <iyy>0.00021796769123546926</iyy>
                    <izz>8.397045203131613e-05</izz>
                    <ixy>-6.974990355367058e-07</ixy>
                    <ixz>-1.6367707827964316e-05</ixz>
                    <iyz>-4.525941773498655e-06</iyz>
                </inertia>
            </inertial>
        </link>


        <!-- Forearm-Wrist Joints -->
        <joint name='forearm_joint' type='revolute'>
            <pose relative_to='forearm'>0 -0.01 0.213 0 0 0</pose>
            <parent>forearm</parent>
            <child>wrist</child>
            <axis>
                <xyz>0 1 0</xyz>
                <limit>
                    <lower>-0.523599</lower>
                    <upper>0.174533</upper>
                    <effort>10</effort>
                    <velocity>2</velocity>
                </limit>
                <dynamics>
                    <damping>1.5</damping>
                    <friction>0.1</friction>
                    <spring_reference>0</spring_reference>
                    <spring_stiffness>0</spring_stiffness>
                </dynamics>
            </axis>
        </joint>

        <joint name='wrist_joint' type='revolute'>
            <pose relative_to='wrist'>0 0 0.034 0 0 0</pose>
            <parent>wrist</parent>
            <child>palm</child>
            <axis>
                <xyz>1 0 0</xyz>
                <limit>
                    <lower>-0.698132</lower>
                    <upper>0.488692</upper>
                    <effort>5</effort>
                    <velocity>2</velocity>
                </limit>
                <dynamics>
                    <damping>1.0</damping>
                    <friction>0.06</friction>
                    <spring_reference>0</spring_reference>
                    <spring_stiffness>0</spring_stiffness>
                </dynamics>
            </axis>
        </joint>


        <!-- Thumb Links -->
        <link name='thumb_base'>
            <pose relative_to='thumb_joint1'>0 0 0 0 0 0</pose>
        </link>

        <link name='thumb_proximal'>
            <self_collide>false</self_collide>
            <pose relative_to='thumb_joint2'>0 0 0 0 0 0</pose>
            <visual name='thumb_proximal_visual'>
                <geometry>
                    <mesh>
                        <uri>meshes/visual/thumb_proximal.dae</uri>
                    </mesh>
                </geometry>
            </visual>
            <collision name='thumb_proximal_collision'>
                <geometry>
                    <mesh>
                        <uri>meshes/collision/thumb_proximal.stl</uri>
                    </mesh>
                </geometry>
            </collision>
            <inertial>
                <pose>-6.37675e-06 -2.60275e-05 0.0167151 0 0 0</pose>
                <mass>0.029845248074084476</mass>
                <inertia>
                    <ixx>8.809503813681578e-06</ixx>
                    <iyy>8.807214493354287e-06</iyy>
                    <izz>1.7686291195911157e-06</izz>
                    <ixy>1.1091315316601925e-09</ixy>
                    <ixz>-7.143938130876406e-09</ixz>
                    <iyz>-2.926129007659203e-09</iyz>
                </inertia>
            </inertial>
        </link>

        <link name='thumb_hub'>
            <pose relative_to='thumb_joint3'>0 0 0 0 0 0</pose>
        </link>

        <link name='thumb_middle'>
            <self_collide>false</self_collide>
            <pose relative_to='thumb_joint4'>0 0 0 0 0 0</pose>
            <visual name='thumb_middle_visual'>
                <geometry>
                    <mesh>
                        <uri>meshes/visual/thumb_middle.dae</uri>
                    </mesh>
                </geometry>
            </visual>
            <collision name='thumb_middle_collision'>
                <geometry>
                    <mesh>
                        <uri>meshes/collision/thumb_middle.stl</uri>
                    </mesh>
                </geometry>
            </collision>
            <inertial>
                <pose>7.47918e-05 -4.50772e-05 0.0153482 0 0 0</pose>
                <mass>0.022009607749522726</mass>
                <inertia>
                    <ixx>4.866417056873123e-06</ixx>
                    <iyy>4.7426247872167984e-06</iyy>
                    <izz>1.12164194910586e-06</izz>
                    <ixy>5.654775451358392e-13</ixy>
                    <ixz>3.3825197205604484e-09</ixz>
                    <iyz>1.4024793995336764e-13</iyz>
                </inertia>
            </inertial>
        </link>

        <link name='thumb_distal'>
            <self_collide>false</self_collide>
            <pose relative_to='thumb_joint5'>0 0 0 0 0 0</pose>
            <visual name='thumb_distal_visual'>
                <geometry>
                    <mesh>
                        <uri>meshes/visual/thumb_distal.dae</uri>
                    </mesh>
                </geometry>
            </visual>
            <collision name='thumb_distal_collision'>
                <geometry>
                    <mesh>
                        <uri>meshes/collision/thumb_distal.stl</uri>
                    </mesh>
                </geometry>
            </collision>
            <inertial>
                <pose>2.55239e-05 0.000159329 0.0160141 0 0 0</pose>
                <mass>0.012191416337983986</mass>
                <inertia>
                    <ixx>1.1139538847236076e-06</ixx>
                    <iyy>1.2119434354416967e-06</iyy>
                    <izz>5.611124622170998e-07</izz>
                    <ixy>-1.5402384459710979e-09</ixy>
                    <ixz>5.280946434116175e-09</ixz>
                    <iyz>6.345744802722492e-08</iyz>
                </inertia>
            </inertial>
        </link>


        <!-- Thumb Joints -->
        <joint name='thumb_joint1' type='revolute'>
            <pose relative_to='palm'>0.034 -0.0085 0.029 0 0.785398 0</pose>
            <parent>palm</parent>
            <child>thumb_base</child>
            <axis>
                <xyz>0 0 -1</xyz>
                <limit>
                    <lower>-1.0472</lower>
                    <upper>1.0472</upper>
                    <effort>4</effort>
                    <velocity>4</velocity>
                </limit>
                <dynamics>
                    <damping>0.9</damping>
                    <friction>0.05</friction>
                    <spring_reference>0</spring_reference>
                    <spring_stiffness>0</spring_stiffness>
                </dynamics>
            </axis>
        </joint>

        <joint name='thumb_joint2' type='revolute'>
            <pose relative_to='thumb_base'>0 0 0 0 0 0</pose>
            <parent>thumb_base</parent>
            <child>thumb_proximal</child>
            <axis>
                <xyz>1 0 0</xyz>
                <limit>
                    <lower>0</lower>
                    <upper>1.22173</upper>
                    <effort>4</effort>
                    <velocity>4</velocity>
                </limit>
                <dynamics>
                    <damping>0.9</damping>
                    <friction>0.05</friction>
                    <spring_reference>0</spring_reference>
                    <spring_stiffness>0</spring_stiffness>
                </dynamics>
            </axis>
        </joint>

        <joint name='thumb_joint3' type='revolute'>
            <pose relative_to='thumb_proximal'>0 0 0.038 0 0 0</pose>
            <parent>thumb_proximal</parent>
            <child>thumb_hub</child>
            <axis>
                <xyz>1 0 0</xyz>
                <limit>
                    <lower>-0.20944</lower>
                    <upper>0.20944</upper>
                    <effort>4</effort>
                    <velocity>4</velocity>
                </limit>
                <dynamics>
                    <damping>0.6</damping>
                    <friction>0.05</friction>
                    <spring_reference>0</spring_reference>
                    <spring_stiffness>0</spring_stiffness>
                </dynamics>
            </axis>
        </joint>

        <joint name='thumb_joint4' type='revolute'>
            <pose relative_to='thumb_hub'>0 0 0 0 0 0</pose>
            <parent>thumb_hub</parent>
            <child>thumb_middle</child>
            <axis>
                <xyz>0 -1 0</xyz>
                <limit>
                    <lower>-0.698132</lower>
                    <upper>0.698132</upper>
                    <effort>4</effort>
                    <velocity>2</velocity>
                </limit>
                <dynamics>
                    <damping>0.6</damping>
                    <friction>0.05</friction>
                    <spring_reference>0</spring_reference>
                    <spring_stiffness>0</spring_stiffness>
                </dynamics>
            </axis>
        </joint>

        <joint name='thumb_joint5' type='revolute'>
            <pose relative_to='thumb_middle'>0 0 0.032 0 0 -1.5708</pose>
            <parent>thumb_middle</parent>
            <child>thumb_distal</child>
            <axis>
                <xyz>1 0 0</xyz>
                <limit>
                    <lower>0</lower>
                    <upper>1.5708</upper>
                    <effort>4</effort>
                    <velocity>4</velocity>
                </limit>
                <dynamics>
                    <damping>0.6</damping>
                    <friction>0.05</friction>
                    <spring_reference>0</spring_reference>
                    <spring_stiffness>0</spring_stiffness>
                </dynamics>
            </axis>
        </joint>


        <!-- Index Finger Links -->
        <link name='index_finger_knuckle'>
            <self_collide>false</self_collide>
            <pose relative_to='index_finger_joint1'>0 0 0.0005 0 0 0</pose>
            <visual name='index_finger_knuckle_visual'>
                <geometry>
                    <mesh>
                        <uri>meshes/visual/knuckle.dae</uri>
                    </mesh>
                </geometry>
            </visual>
            <collision name='index_finger_knuckle_collision'>
                <geometry>
                    <mesh>
                        <uri>meshes/collision/knuckle.stl</uri>
                    </mesh>
                </geometry>
            </collision>
            <inertial>
                <pose>-1.04918e-05 0.000479353 -0.000502517 0 0 0</pose>
                <mass>0.0035070211983386054</mass>
                <inertia>
                    <ixx>1.2613822953446773e-07</ixx>
                    <iyy>1.11133938741452e-07</iyy>
                    <izz>1.08204456507778e-07</izz>
                    <ixy>-2.472822460210415e-10</ixy>
                    <ixz>-1.164468880051402e-10</ixz>
                    <iyz>2.0243718895568695e-09</iyz>
                </inertia>
            </inertial>
        </link>

        <link name='index_finger_proximal'>
            <self_collide>false</self_collide>
            <pose relative_to='index_finger_joint2'>0 0 0 0 0 0</pose>
            <visual name='index_finger_proximal_visual'>
                <geometry>
                    <mesh>
                        <uri>meshes/visual/finger_proximal.dae</uri>
                    </mesh>
                </geometry>
            </visual>
            <collision name='index_finger_proximal_collision'>
                <geometry>
                    <mesh>
                        <uri>meshes/collision/finger_proximal.stl</uri>
                    </mesh>
                </geometry>
            </collision>
            <inertial>
                <pose>1.36521e-06 5.46075e-05 0.0253411 0 0 0</pose>
                <mass>0.016546729448686223</mass>
                <inertia>
                    <ixx>3.2790314425912466e-06</ixx>
                    <iyy>3.426407472161571e-06</iyy>
                    <izz>7.483590841347604e-07</izz>
                    <ixy>2.3206915370866564e-12</ixy>
                    <ixz>-1.505092275461155e-10</ixz>
                    <iyz>-3.496779879303333e-08</iyz>
                </inertia>
            </inertial>
        </link>

        <link name='index_finger_middle'>
            <self_collide>false</self_collide>
            <pose relative_to='index_finger_joint3'>0 0 0 0 0 0</pose>
            <visual name='index_finger_middle_visual'>
                <geometry>
                    <mesh>
                        <uri>meshes/visual/finger_middle.dae</uri>
                    </mesh>
                </geometry>
            </visual>
            <collision name='index_finger_middle_collision'>
                <geometry>
                    <mesh>
                        <uri>meshes/collision/finger_middle.stl</uri>
                    </mesh>
                </geometry>
            </collision>
            <inertial>
                <pose>-2.71515e-06 -3.22073e-05 0.0115512 0 0 0</pose>
                <mass>0.012408560609951024</mass>
                <inertia>
                    <ixx>1.5832484254307727e-06</ixx>
                    <iyy>1.6564644723522258e-06</iyy>
                    <izz>4.666927966755565e-07</izz>
                    <ixy>2.712627657702685e-13</ixy>
                    <ixz>1.708810927508445e-11</ixz>
                    <iyz>3.05685228626636e-10</iyz>
                </inertia>
            </inertial>
        </link>

        <link name='index_finger_distal'>
            <self_collide>false</self_collide>
            <pose relative_to='index_finger_joint4'>0 0 0 0 0 0</pose>
            <visual name='index_finger_distal_visual'>
                <geometry>
                    <mesh>
                        <uri>meshes/visual/finger_distal.dae</uri>
                    </mesh>
                </geometry>
            </visual>
            <collision name='index_finger_distal_collision'>
                <geometry>
                    <mesh>
                        <uri>meshes/collision/finger_distal.stl</uri>
                    </mesh>
                </geometry>
            </collision>
            <inertial>
                <pose>6.76198e-09 -0.000120361 0.0153038 0 0 0</pose>
                <mass>0.005483958097427844</mass>
                <inertia>
                    <ixx>2.8345521306539727e-07</ixx>
                    <iyy>3.1564663297634386e-07</iyy>
                    <izz>1.681513616992521e-07</izz>
                    <ixy>3.258702375668527e-13</ixy>
                    <ixz>2.4425287458423485e-13</ixz>
                    <iyz>9.87273750852163e-10</iyz>
                </inertia>
            </inertial>
        </link>


        <!-- Index Finger Joints -->
        <joint name='index_finger_joint1' type='revolute'>
            <pose relative_to='palm'>0.033 0 0.095 0 0 0</pose>
            <parent>palm</parent>
            <child>index_finger_knuckle</child>
            <axis>
                <xyz>0 -1 0</xyz>
                <limit>
                    <lower>-0.349066</lower>
                    <upper>0.349066</upper>
                    <effort>4</effort>
                    <velocity>2</velocity>
                </limit>
                <dynamics>
                    <damping>0.9</damping>
                    <friction>0.05</friction>
                    <spring_reference>0</spring_reference>
                    <spring_stiffness>0</spring_stiffness>
                </dynamics>
            </axis>
        </joint>

        <joint name='index_finger_joint2' type='revolute'>
            <pose relative_to='index_finger_knuckle'>0 0 0 0 0 0</pose>
            <parent>index_finger_knuckle</parent>
            <child>index_finger_proximal</child>
            <axis>
                <xyz>1 0 0</xyz>
                <limit>
                    <lower>0</lower>
                    <upper>1.5708</upper>
                    <effort>4</effort>
                    <velocity>2</velocity>
                </limit>
                <dynamics>
                    <damping>0.6</damping>
                    <friction>0.05</friction>
                    <spring_reference>0</spring_reference>
                    <spring_stiffness>0</spring_stiffness>
                </dynamics>
            </axis>
        </joint>

        <joint name='index_finger_joint3' type='revolute'>
            <pose relative_to='index_finger_proximal'>0 0 0.045 0 0 0</pose>
            <parent>index_finger_proximal</parent>
            <child>index_finger_middle</child>
            <axis>
                <xyz>1 0 0</xyz>
                <limit>
                    <lower>0</lower>
                    <upper>1.5708</upper>
                    <effort>4</effort>
                    <velocity>2</velocity>
                </limit>
                <dynamics>
                    <damping>0.6</damping>
                    <friction>0.05</friction>
                    <spring_reference>0</spring_reference>
                    <spring_stiffness>0</spring_stiffness>
                </dynamics>
            </axis>
        </joint>

        <joint name='index_finger_joint4' type='revolute'>
            <pose relative_to='index_finger_middle'>0 0 0.025 0 0 0</pose>
            <parent>index_finger_middle</parent>
            <child>index_finger_distal</child>
            <axis>
                <xyz>1 0 0</xyz>
                <limit>
                    <lower>0</lower>
                    <upper>1.5708</upper>
                    <effort>4</effort>
                    <velocity>2</velocity>
                </limit>
                <dynamics>
                    <damping>0.6</damping>
                    <friction>0.05</friction>
                    <spring_reference>0</spring_reference>
                    <spring_stiffness>0</spring_stiffness>
                </dynamics>
            </axis>
        </joint>


        <!-- Middle Finger Links -->
        <link name='middle_finger_knuckle'>
            <self_collide>false</self_collide>
            <pose relative_to='middle_finger_joint1'>0 0 0.0005 0 0 0</pose>
            <visual name='middle_finger_knuckle_visual'>
                <geometry>
                    <mesh>
                        <uri>meshes/visual/knuckle.dae</uri>
                    </mesh>
                </geometry>
            </visual>
            <collision name='middle_finger_knuckle_collision'>
                <geometry>
                    <mesh>
                        <uri>meshes/collision/knuckle.stl</uri>
                    </mesh>
                </geometry>
            </collision>
            <inertial>
                <pose>-1.04918e-05 0.000479353 -0.000502517 0 0 0</pose>
                <mass>0.0035070211983386054</mass>
                <inertia>
                    <ixx>1.2613822953446773e-07</ixx>
                    <iyy>1.11133938741452e-07</iyy>
                    <izz>1.08204456507778e-07</izz>
                    <ixy>-2.472822460210415e-10</ixy>
                    <ixz>-1.164468880051402e-10</ixz>
                    <iyz>2.0243718895568695e-09</iyz>
                </inertia>
            </inertial>
        </link>

        <link name='middle_finger_proximal'>
            <self_collide>false</self_collide>
            <pose relative_to='middle_finger_joint2'>0 0 0 0 0 0</pose>
            <visual name='middle_finger_proximal_visual'>
                <geometry>
                    <mesh>
                        <uri>meshes/visual/finger_proximal.dae</uri>
                    </mesh>
                </geometry>
            </visual>
            <collision name='middle_finger_proximal_collision'>
                <geometry>
                    <mesh>
                        <uri>meshes/collision/finger_proximal.stl</uri>
                    </mesh>
                </geometry>
            </collision>
            <inertial>
                <pose>1.36521e-06 5.46075e-05 0.0253411 0 0 0</pose>
                <mass>0.016546729448686223</mass>
                <inertia>
                    <ixx>3.2790314425912466e-06</ixx>
                    <iyy>3.426407472161571e-06</iyy>
                    <izz>7.483590841347604e-07</izz>
                    <ixy>2.3206915370866564e-12</ixy>
                    <ixz>-1.505092275461155e-10</ixz>
                    <iyz>-3.496779879303333e-08</iyz>
                </inertia>
            </inertial>
        </link>

        <link name='middle_finger_middle'>
            <self_collide>false</self_collide>
            <pose relative_to='middle_finger_joint3'>0 0 0 0 0 0</pose>
            <visual name='middle_finger_middle_visual'>
                <geometry>
                    <mesh>
                        <uri>meshes/visual/finger_middle.dae</uri>
                    </mesh>
                </geometry>
            </visual>
            <collision name='middle_finger_middle_collision'>
                <geometry>
                    <mesh>
                        <uri>meshes/collision/finger_middle.stl</uri>
                    </mesh>
                </geometry>
            </collision>
            <inertial>
                <pose>-2.71515e-06 -3.22073e-05 0.0115512 0 0 0</pose>
                <mass>0.012408560609951024</mass>
                <inertia>
                    <ixx>1.5832484254307727e-06</ixx>
                    <iyy>1.6564644723522258e-06</iyy>
                    <izz>4.666927966755565e-07</izz>
                    <ixy>2.712627657702685e-13</ixy>
                    <ixz>1.708810927508445e-11</ixz>
                    <iyz>3.05685228626636e-10</iyz>
                </inertia>
            </inertial>
        </link>

        <link name='middle_finger_distal'>
            <self_collide>false</self_collide>
            <pose relative_to='middle_finger_joint4'>0 0 0 0 0 0</pose>
            <visual name='middle_finger_distal_visual'>
                <geometry>
                    <mesh>
                        <uri>meshes/visual/finger_distal.dae</uri>
                    </mesh>
                </geometry>
            </visual>
            <collision name='middle_finger_distal_collision'>
                <geometry>
                    <mesh>
                        <uri>meshes/collision/finger_distal.stl</uri>
                    </mesh>
                </geometry>
            </collision>
            <inertial>
                <pose>6.76198e-09 -0.000120361 0.0153038 0 0 0</pose>
                <mass>0.005483958097427844</mass>
                <inertia>
                    <ixx>2.8345521306539727e-07</ixx>
                    <iyy>3.1564663297634386e-07</iyy>
                    <izz>1.681513616992521e-07</izz>
                    <ixy>3.258702375668527e-13</ixy>
                    <ixz>2.4425287458423485e-13</ixz>
                    <iyz>9.87273750852163e-10</iyz>
                </inertia>
            </inertial>
        </link>




        <!-- Middle Finger Joints -->
        <joint name='middle_finger_joint1' type='revolute'>
            <pose relative_to='palm'>0.011 0 0.099 0 0 0</pose>
            <parent>palm</parent>
            <child>middle_finger_knuckle</child>
            <axis>
                <xyz>0 -1 0</xyz>
                <limit>
                    <lower>-0.349066</lower>
                    <upper>0.349066</upper>
                    <effort>4</effort>
                    <velocity>2</velocity>
                </limit>
                <dynamics>
                    <damping>0.9</damping>
                    <friction>0.05</friction>
                    <spring_reference>0</spring_reference>
                    <spring_stiffness>0</spring_stiffness>
                </dynamics>
            </axis>
        </joint>

        <joint name='middle_finger_joint2' type='revolute'>
            <pose relative_to='middle_finger_knuckle'>0 0 0 0 0 0</pose>
            <parent>middle_finger_knuckle</parent>
            <child>middle_finger_proximal</child>
            <axis>
                <xyz>1 0 0</xyz>
                <limit>
                    <lower>0</lower>
                    <upper>1.5708</upper>
                    <effort>4</effort>
                    <velocity>2</velocity>
                </limit>
                <dynamics>
                    <damping>0.6</damping>
                    <friction>0.05</friction>
                    <spring_reference>0</spring_reference>
                    <spring_stiffness>0</spring_stiffness>
                </dynamics>
            </axis>
        </joint>

        <joint name='middle_finger_joint3' type='revolute'>
            <pose relative_to='middle_finger_proximal'>0 0 0.045 0 0 0</pose>
            <parent>middle_finger_proximal</parent>
            <child>middle_finger_middle</child>
            <axis>
                <xyz>1 0 0</xyz>
                <limit>
                    <lower>0</lower>
                    <upper>1.5708</upper>
                    <effort>4</effort>
                    <velocity>2</velocity>
                </limit>
                <dynamics>
                    <damping>0.6</damping>
                    <friction>0.05</friction>
                    <spring_reference>0</spring_reference>
                    <spring_stiffness>0</spring_stiffness>
                </dynamics>
            </axis>
        </joint>

        <joint name='middle_finger_joint4' type='revolute'>
            <pose relative_to='middle_finger_middle'>0 0 0.025 0 0 0</pose>
            <parent>middle_finger_middle</parent>
            <child>middle_finger_distal</child>
            <axis>
                <xyz>1 0 0</xyz>
                <limit>
                    <lower>0</lower>
                    <upper>1.5708</upper>
                    <effort>4</effort>
                    <velocity>2</velocity>
                </limit>
                <dynamics>
                    <damping>0.6</damping>
                    <friction>0.05</friction>
                    <spring_reference>0</spring_reference>
                    <spring_stiffness>0</spring_stiffness>
                </dynamics>
            </axis>
        </joint>


        <!-- Ring Finger Links -->
        <link name='ring_finger_knuckle'>
            <self_collide>false</self_collide>
            <pose relative_to='ring_finger_joint1'>0 0 0.0005 0 0 0</pose>
            <visual name='ring_finger_knuckle_visual'>
                <geometry>
                    <mesh>
                        <uri>meshes/visual/knuckle.dae</uri>
                    </mesh>
                </geometry>
            </visual>
            <collision name='ring_finger_knuckle_collision'>
                <geometry>
                    <mesh>
                        <uri>meshes/collision/knuckle.stl</uri>
                    </mesh>
                </geometry>
            </collision>
            <inertial>
                <pose>-1.04918e-05 0.000479353 -0.000502517 0 0 0</pose>
                <mass>0.0035070211983386054</mass>
                <inertia>
                    <ixx>1.2613822953446773e-07</ixx>
                    <iyy>1.11133938741452e-07</iyy>
                    <izz>1.08204456507778e-07</izz>
                    <ixy>-2.472822460210415e-10</ixy>
                    <ixz>-1.164468880051402e-10</ixz>
                    <iyz>2.0243718895568695e-09</iyz>
                </inertia>
            </inertial>
        </link>

        <link name='ring_finger_proximal'>
            <self_collide>false</self_collide>
            <pose relative_to='ring_finger_joint2'>0 0 0 0 0 0</pose>
            <visual name='ring_finger_proximal_visual'>
                <geometry>
                    <mesh>
                        <uri>meshes/visual/finger_proximal.dae</uri>
                    </mesh>
                </geometry>
            </visual>
            <collision name='ring_finger_proximal_collision'>
                <geometry>
                    <mesh>
                        <uri>meshes/collision/finger_proximal.stl</uri>
                    </mesh>
                </geometry>
            </collision>
            <inertial>
                <pose>1.36521e-06 5.46075e-05 0.0253411 0 0 0</pose>
                <mass>0.016546729448686223</mass>
                <inertia>
                    <ixx>3.2790314425912466e-06</ixx>
                    <iyy>3.426407472161571e-06</iyy>
                    <izz>7.483590841347604e-07</izz>
                    <ixy>2.3206915370866564e-12</ixy>
                    <ixz>-1.505092275461155e-10</ixz>
                    <iyz>-3.496779879303333e-08</iyz>
                </inertia>
            </inertial>
        </link>

        <link name='ring_finger_middle'>
            <self_collide>false</self_collide>
            <pose relative_to='ring_finger_joint3'>0 0 0 0 0 0</pose>
            <visual name='ring_finger_middle_visual'>
                <geometry>
                    <mesh>
                        <uri>meshes/visual/finger_middle.dae</uri>
                    </mesh>
                </geometry>
            </visual>
            <collision name='ring_finger_middle_collision'>
                <geometry>
                    <mesh>
                        <uri>meshes/collision/finger_middle.stl</uri>
                    </mesh>
                </geometry>
            </collision>
            <inertial>
                <pose>-2.71515e-06 -3.22073e-05 0.0115512 0 0 0</pose>
                <mass>0.012408560609951024</mass>
                <inertia>
                    <ixx>1.5832484254307727e-06</ixx>
                    <iyy>1.6564644723522258e-06</iyy>
                    <izz>4.666927966755565e-07</izz>
                    <ixy>2.712627657702685e-13</ixy>
                    <ixz>1.708810927508445e-11</ixz>
                    <iyz>3.05685228626636e-10</iyz>
                </inertia>
            </inertial>
        </link>

        <link name='ring_finger_distal'>
            <self_collide>false</self_collide>
            <pose relative_to='ring_finger_joint4'>0 0 0 0 0 0</pose>
            <visual name='ring_finger_distal_visual'>
                <geometry>
                    <mesh>
                        <uri>meshes/visual/finger_distal.dae</uri>
                    </mesh>
                </geometry>
            </visual>
            <collision name='ring_finger_distal_collision'>
                <geometry>
                    <mesh>
                        <uri>meshes/collision/finger_distal.stl</uri>
                    </mesh>
                </geometry>
            </collision>
            <inertial>
                <pose>6.76198e-09 -0.000120361 0.0153038 0 0 0</pose>
                <mass>0.005483958097427844</mass>
                <inertia>
                    <ixx>2.8345521306539727e-07</ixx>
                    <iyy>3.1564663297634386e-07</iyy>
                    <izz>1.681513616992521e-07</izz>
                    <ixy>3.258702375668527e-13</ixy>
                    <ixz>2.4425287458423485e-13</ixz>
                    <iyz>9.87273750852163e-10</iyz>
                </inertia>
            </inertial>
        </link>


        <!-- Ring Finger Joints -->
        <joint name='ring_finger_joint1' type='revolute'>
            <pose relative_to='palm'>-0.011 0 0.095 0 0 0</pose>
            <parent>palm</parent>
            <child>ring_finger_knuckle</child>
            <axis>
                <xyz>0 1 0</xyz>
                <limit>
                    <lower>-0.349066</lower>
                    <upper>0.349066</upper>
                    <effort>4</effort>
                    <velocity>2</velocity>
                </limit>
                <dynamics>
                    <damping>0.9</damping>
                    <friction>0.05</friction>
                    <spring_reference>0</spring_reference>
                    <spring_stiffness>0</spring_stiffness>
                </dynamics>
            </axis>
        </joint>

        <joint name='ring_finger_joint2' type='revolute'>
            <pose relative_to='ring_finger_knuckle'>0 0 0 0 0 0</pose>
            <parent>ring_finger_knuckle</parent>
            <child>ring_finger_proximal</child>
            <axis>
                <xyz>1 0 0</xyz>
                <limit>
                    <lower>0</lower>
                    <upper>1.5708</upper>
                    <effort>4</effort>
                    <velocity>2</velocity>
                </limit>
                <dynamics>
                    <damping>0.6</damping>
                    <friction>0.05</friction>
                    <spring_reference>0</spring_reference>
                    <spring_stiffness>0</spring_stiffness>
                </dynamics>
            </axis>
        </joint>

        <joint name='ring_finger_joint3' type='revolute'>
            <pose relative_to='ring_finger_proximal'>0 0 0.045 0 0 0</pose>
            <parent>ring_finger_proximal</parent>
            <child>ring_finger_middle</child>
            <axis>
                <xyz>1 0 0</xyz>
                <limit>
                    <lower>0</lower>
                    <upper>1.5708</upper>
                    <effort>4</effort>
                    <velocity>2</velocity>
                </limit>
                <dynamics>
                    <damping>0.6</damping>
                    <friction>0.05</friction>
                    <spring_reference>0</spring_reference>
                    <spring_stiffness>0</spring_stiffness>
                </dynamics>
            </axis>
        </joint>

        <joint name='ring_finger_joint4' type='revolute'>
            <pose relative_to='ring_finger_middle'>0 0 0.025 0 0 0</pose>
            <parent>ring_finger_middle</parent>
            <child>ring_finger_distal</child>
            <axis>
                <xyz>1 0 0</xyz>
                <limit>
                    <lower>0</lower>
                    <upper>1.5708</upper>
                    <effort>4</effort>
                    <velocity>2</velocity>
                </limit>
                <dynamics>
                    <damping>0.6</damping>
                    <friction>0.05</friction>
                    <spring_reference>0</spring_reference>
                    <spring_stiffness>0</spring_stiffness>
                </dynamics>
            </axis>
        </joint>


        <!-- Little Finger Links -->
        <link name='little_finger_metacarpal'>
            <self_collide>false</self_collide>
            <pose relative_to='little_finger_joint1'>0 0 0 0 0 0</pose>
            <visual name='little_finger_metacarpal_visual'>
                <geometry>
                    <mesh>
                        <uri>meshes/visual/metacarpal.dae</uri>
                    </mesh>
                </geometry>
            </visual>
            <collision name='little_finger_metacarpal_collision'>
                <geometry>
                    <mesh>
                        <uri>meshes/collision/metacarpal.stl</uri>
                    </mesh>
                </geometry>
            </collision>
            <inertial>
                <pose>0.00256076 0.000530977 0.0357809 0 0 0</pose>
                <mass>0.028712737421138307</mass>
                <inertia>
                    <ixx>6.379834557352727e-06</ixx>
                    <iyy>7.213134316020707e-06</iyy>
                    <izz>3.1646574521542297e-06</izz>
                    <ixy>4.254904885572987e-08</ixy>
                    <ixz>8.679884151458579e-07</ixz>
                    <iyz>-1.2278795447712084e-07</iyz>
                </inertia>
            </inertial>
        </link>

        <link name='little_finger_knuckle'>
            <self_collide>false</self_collide>
            <pose relative_to='little_finger_joint2'>0 0 0.0005 0 0 0</pose>
            <visual name='little_finger_knuckle_visual'>
                <geometry>
                    <mesh>
                        <uri>meshes/visual/knuckle.dae</uri>
                    </mesh>
                </geometry>
            </visual>
            <collision name='little_finger_knuckle_collision'>
                <geometry>
                    <mesh>
                        <uri>meshes/collision/knuckle.stl</uri>
                    </mesh>
                </geometry>
            </collision>
            <inertial>
                <pose>-1.04918e-05 0.000479353 -0.000502517 0 0 0</pose>
                <mass>0.0035070211983386054</mass>
                <inertia>
                    <ixx>1.2613822953446773e-07</ixx>
                    <iyy>1.11133938741452e-07</iyy>
                    <izz>1.08204456507778e-07</izz>
                    <ixy>-2.472822460210415e-10</ixy>
                    <ixz>-1.164468880051402e-10</ixz>
                    <iyz>2.0243718895568695e-09</iyz>
                </inertia>
            </inertial>
        </link>

        <link name='little_finger_proximal'>
            <self_collide>false</self_collide>
            <pose relative_to='little_finger_joint3'>0 0 0 0 0 0</pose>
            <visual name='little_finger_proximal_visual'>
                <geometry>
                    <mesh>
                        <uri>meshes/visual/finger_proximal.dae</uri>
                    </mesh>
                </geometry>
            </visual>
            <collision name='little_finger_proximal_collision'>
                <geometry>
                    <mesh>
                        <uri>meshes/collision/finger_proximal.stl</uri>
                    </mesh>
                </geometry>
            </collision>
            <inertial>
                <pose>1.36521e-06 5.46075e-05 0.0253411 0 0 0</pose>
                <mass>0.016546729448686223</mass>
                <inertia>
                    <ixx>3.2790314425912466e-06</ixx>
                    <iyy>3.426407472161571e-06</iyy>
                    <izz>7.483590841347604e-07</izz>
                    <ixy>2.3206915370866564e-12</ixy>
                    <ixz>-1.505092275461155e-10</ixz>
                    <iyz>-3.496779879303333e-08</iyz>
                </inertia>
            </inertial>
        </link>

        <link name='little_finger_middle'>
            <self_collide>false</self_collide>
            <pose relative_to='little_finger_joint4'>0 0 0 0 0 0</pose>
            <visual name='little_finger_middle_visual'>
                <geometry>
                    <mesh>
                        <uri>meshes/visual/finger_middle.dae</uri>
                    </mesh>
                </geometry>
            </visual>
            <collision name='little_finger_middle_collision'>
                <geometry>
                    <mesh>
                        <uri>meshes/collision/finger_middle.stl</uri>
                    </mesh>
                </geometry>
            </collision>
            <inertial>
                <pose>-2.71515e-06 -3.22073e-05 0.0115512 0 0 0</pose>
                <mass>0.012408560609951024</mass>
                <inertia>
                    <ixx>1.5832484254307727e-06</ixx>
                    <iyy>1.6564644723522258e-06</iyy>
                    <izz>4.666927966755565e-07</izz>
                    <ixy>2.712627657702685e-13</ixy>
                    <ixz>1.708810927508445e-11</ixz>
                    <iyz>3.05685228626636e-10</iyz>
                </inertia>
            </inertial>
        </link>

        <link name='little_finger_distal'>
            <self_collide>false</self_collide>
            <pose relative_to='little_finger_joint5'>0 0 0 0 0 0</pose>
            <visual name='little_finger_distal_visual'>
                <geometry>
                    <mesh>
                        <uri>meshes/visual/finger_distal.dae</uri>
                    </mesh>
                </geometry>
            </visual>
            <collision name='little_finger_distal_collision'>
                <geometry>
                    <mesh>
                        <uri>meshes/collision/finger_distal.stl</uri>
                    </mesh>
                </geometry>
            </collision>
            <inertial>
                <pose>6.76198e-09 -0.000120361 0.0153038 0 0 0</pose>
                <mass>0.005483958097427844</mass>
                <inertia>
                    <ixx>2.8345521306539727e-07</ixx>
                    <iyy>3.1564663297634386e-07</iyy>
                    <izz>1.681513616992521e-07</izz>
                    <ixy>3.258702375668527e-13</ixy>
                    <ixz>2.4425287458423485e-13</ixz>
                    <iyz>9.87273750852163e-10</iyz>
                </inertia>
            </inertial>
        </link>


        <!-- Little Finger Joints -->
        <joint name='little_finger_joint1' type='revolute'>
            <pose relative_to='palm'>-0.033 0 0.02071 0 0 0</pose>
            <parent>palm</parent>
            <child>little_finger_metacarpal</child>
            <axis>
                <xyz>0.573576 0 0.819152</xyz>
                <limit>
                    <lower>0</lower>
                    <upper>0.785398</upper>
                    <effort>4</effort>
                    <velocity>2</velocity>
                </limit>
                <dynamics>
                    <damping>0.9</damping>
                    <friction>0.05</friction>
                    <spring_reference>0</spring_reference>
                    <spring_stiffness>0</spring_stiffness>
                </dynamics>
            </axis>
        </joint>

        <joint name='little_finger_joint2' type='revolute'>
            <pose relative_to='little_finger_metacarpal'>0 0 0.06579 0 0 0</pose>
            <parent>little_finger_metacarpal</parent>
            <child>little_finger_knuckle</child>
            <axis>
                <xyz>0 1 0</xyz>
                <limit>
                    <lower>-0.349066</lower>
                    <upper>0.349066</upper>
                    <effort>4</effort>
                    <velocity>2</velocity>
                </limit>
                <dynamics>
                    <damping>0.9</damping>
                    <friction>0.05</friction>
                    <spring_reference>0</spring_reference>
                    <spring_stiffness>0</spring_stiffness>
                </dynamics>
            </axis>
        </joint>

        <joint name='little_finger_joint3' type='revolute'>
            <pose relative_to='little_finger_knuckle'>0 0 0 0 0 0</pose>
            <parent>little_finger_knuckle</parent>
            <child>little_finger_proximal</child>
            <axis>
                <xyz>1 0 0</xyz>
                <limit>
                    <lower>0</lower>
                    <upper>1.5708</upper>
                    <effort>4</effort>
                    <velocity>2</velocity>
                </limit>
                <dynamics>
                    <damping>0.6</damping>
                    <friction>0.05</friction>
                    <spring_reference>0</spring_reference>
                    <spring_stiffness>0</spring_stiffness>
                </dynamics>
            </axis>
        </joint>

        <joint name='little_finger_joint4' type='revolute'>
            <pose relative_to='little_finger_proximal'>0 0 0.045 0 0 0</pose>
            <parent>little_finger_proximal</parent>
            <child>little_finger_middle</child>
            <axis>
                <xyz>1 0 0</xyz>
                <limit>
                    <lower>0</lower>
                    <upper>1.5708</upper>
                    <effort>4</effort>
                    <velocity>2</velocity>
                </limit>
                <dynamics>
                    <damping>0.6</damping>
                    <friction>0.05</friction>
                    <spring_reference>0</spring_reference>
                    <spring_stiffness>0</spring_stiffness>
                </dynamics>
            </axis>
        </joint>

        <joint name='little_finger_joint5' type='revolute'>
            <pose relative_to='little_finger_middle'>0 0 0.025 0 0 0</pose>
            <parent>little_finger_middle</parent>
            <child>little_finger_distal</child>
            <axis>
                <xyz>1 0 0</xyz>
                <limit>
                    <lower>0</lower>
                    <upper>1.5708</upper>
                    <effort>4</effort>
                    <velocity>2</velocity>
                </limit>
                <dynamics>
                    <damping>0.6</damping>
                    <friction>0.05</friction>
                    <spring_reference>0</spring_reference>
                    <spring_stiffness>0</spring_stiffness>
                </dynamics>
            </axis>
        </joint>

    </model>
</sdf>
